Workbook
Name DistinctIssues: #REF!

Sheet Plan
A1: Name | B1: Date | C1: Process | D1: Est Hours | F1: Project Plan | G1: % | H1: Hours
A2: nachiket.kulawade | B2: 45204 | C2: Testing | D2: 4 | F2: Testing & Report Writing | G2: 0.65 | H2: {=Project[Budgetted Hours by Sales]*G2} -> 212.1535
A3: harshada.morje | B3: 45204 | C3: Testing | D3: 4 | F3: QA | G3: 0.25 | H3: {=Project[Budgetted Hours by Sales]*G3} -> 81.5975
A4: naveen.lagishetty | B4: 45204 | C4: Testing | D4: 4 | F4: PM | G4: 0.1 | H4: {=Project[Budgetted Hours by Sales]*G4} -> 32.639
A5: nachiket.kulawade | B5: 45205 | C5: Testing | D5: 4
A6: harshada.morje | B6: 45205 | C6: Testing | D6: 4
A7: naveen.lagishetty | B7: 45205 | C7: Testing | D7: 4
A8: nachiket.kulawade | B8: 45205 | C8: Report | D8: 4
A9: harshada.morje | B9: 45205 | C9: Report | D9: 4
A10: naveen.lagishetty | B10: 45205 | C10: Report | D10: 4
A11: nachiket.kulawade | B11: 45208 | C11: Testing | D11: 4
A12: harshada.morje | B12: 45208 | C12: Testing | D12: 4
A13: naveen.lagishetty | B13: 45208 | C13: Testing | D13: 4
A14: nachiket.kulawade | B14: 45208 | C14: Report | D14: 4
A15: harshada.morje | B15: 45208 | C15: Report | D15: 4
A16: naveen.lagishetty | B16: 45208 | C16: Report | D16: 4
... A70: manasi.varma | B70: 45219 | C70: QA | D70: 3

Sheet Project
A1: Name of Project | B1: Client | C1: Type of Report | D1: VPAT Needed | E1: What are we Testing | F1: What is the Unit of Testing | G1: No. of Units Being Tested as per project scope | H1: No. of Units in URL Sheet | I1: Initial Stage Units | J1: Project Status | K1: Estimated Start Date | L1: Estimated Delivery Date | M1: Delivered Date | N1: Delivered Time | O1: Budgetted Hours by Sales | P1: Additional Hours | Q1: New Members | R1: Total Team | S1: Mentor | T1: APM | U1: Captain | V1: No. of Working Days | W1: Planned Hours | X1: Actual Hours | Y1: Est VPAT | Z1: Total Issues | AA1: Total Issues Delivered | AB1: Total Perfect Issues
A2: MyLab Marketing VPAT Audit | B2: Pearson | C2: Bug - Every Bug on Every Page | D2: WCAG 2.1 | E2: Web | F2: Page/URL | G2: 70 | H2: 35 | I2: 4 | J2: Delivered | K2: 45204 | L2: 45219 | M2: 45219 | N2: Before 9 pm | O2: 326.39 | P2: =Project[[#This Row],[New Members]]*(Project[[#This Row],[Budgetted Hours by Sales]]*0.7%) -> 0 | Q2: 0 | R2: =ROWS(Team[]) -> 11 | S2: jayshree.sharma | T2: chhayanka.amberkar | U2: manasi.varma | V2: =NETWORKDAYS(Project[[#This Row],[Estimated Start Date]],Project[[#This Row],[Estimated Delivery Date]],HolidayList[]) -> 12 | W2: =SUM(Plan!D:D) -> 250 | X2: =Production!H3 -> 68.25 | Y2: =IF(Project[[#This Row],[VPAT Needed]]=0,0,IF(Project[[#This Row],[VPAT Needed]]="WCAG 2.0",Variables!E55,Variables!E56)) -> 24 | Z2: =(COUNTA('Final Report'!BC:BC)-1) -> 998 | AA2: =(COUNTIFS('Final Report'!AX:AX,"*Approved after Fixing*"))+(COUNTIFS('Final Report'!AX:AX,"*Yes Perfect Issue*"))+(COUNTIFS('Final Report'!AX:AX,"*New Issue - QA*"))+(COUNTIFS('Final Report'!AX:AX,"*New Issue*")) -> 14 | AB2: =COUNTIF('Final Report'!BK:BK,"*Perfect*") -> 0
G3: =IF(I2=B11,"Units are correct",IF(I2>B11,"Check why we testing LESS than needed","Check why we testing MORE than needed")) -> Check why we testing MORE than needed
A8: Automated tools | B8: Assistive Technologies | C8: Web Browsers | D8: How much Testing in % or Numbers
A9: Mark up validators | B9: JAWS 2022 | C9: Chrome
A10: Accessibility toolbars | B10: NVDA 2022 | C10: FF
A11: Color Contrast Analyzer | B11: VoiceOver | C11: Safari-Mac
A12: ZoomText | B12: VoiceOver | C12: iOS - Safari / iOS App
A13: Dragon | B13: TalkBack | C13: Android - Chrome / Android App
A15: Note: Please put all the team members including Associates, APM, TL
A17: Name | B17: Role
A18: nachiket.kulawade | B18: FT Tester
A19: harshada.morje | B19: FT Tester
A20: naveen.lagishetty | B20: FT Tester
A21: irfan.shaikh | B21: FT Tester
A22: kumar.reddy | B22: FT Tester
A23: manasi.varma | B23: Captain
A24: jayshree.sharma | B24: Mentor
A25: chhayanka.amberkar | B25: APM
A26: prerna.rane | B26: FT QA
A27: dilip.dharia | B27: AT Tester
A28: manisha.prakash
A35: Steps to Reproduce Start for Web | B35: Steps to Reproduce Start for App | D35: Component Keyword | F35: Login | H35: Labels
D36: Accessibility, Audit, Marketing, MLM-XL, MLVISION, MyLab, US, VPAT | H36: Accessibility, Audit, Marketing, MLM-XL, MLVISION, MyLab, US, VPAT
D42: Tested on
D43: Windows: 11 MAC OS: 12 iOS: 15 Android OS: 10

Sheet Production
A1: Employee | B1: Date | C1: Process | D1: No. of Hours | E1: No. of Units | G1: Timelines | H1: Numbers | K1: Row Labels | L1: No. of Issues | M1: Self QC Score | N1: BB Self QC Score | O1: QC Percentage | Q1: Row Labels | R1: No. of Issues | S1: Self QC QA Score | T1: BB Self QC QA Score | U1: QA Percentage | W1: Count of Finalized | X1: Column Labels | AL1: Status | AM1: (All) | AO1: Status | AP1: (All) | AS1: Count of Issue Name | AT1: Column Labels | AZ1: Issue Tested By | BA1: Count of Writing Score
A2: kumar.reddy | B2: 45208 | C2: Testing | D2: 3 | E2: 3 | G2: Project Est Hours | H2: =Project[[#This Row],[Budgetted Hours by Sales]]+Project[[#This Row],[Additional Hours]] -> 326.39 | K2: (blank) | L2: 59 | O2: 0 | Q2: (blank) | R2: 66 | U2: 0 | W2: Row Labels | X2: (blank) | Y2: To Be Approved | Z2: Delete - QA | AA2: Yes Perfect Issue | AB2: Approved after Fixing | AC2: Grand Total | AS2: Row Labels | AT2: (blank) | AU2: Grand Total | AZ2: (blank)
A3: naveen.lagishetty | B3: 45208 | C3: Testing | D3: 6 | E3: 6 | G3: Actual Production Hours | H3: =(SUM(D:D)-(SUMIF(C:C,"PM",D:D)+SUMIF(C:C,"Meeting",D:D))) -> 68.25 | K3: naveen.lagishetty | L3: 13 | M3: 50 | N3: 50 | O3: 100 | Q3: manasi.varma | R3: 3 | S3: 15 | U3: 0 | W3: (blank) | AL3: Row Labels | AM3: Wastage | AO3: Row Labels | AP3: New Issues | AS3: (blank) | AT3: 59 | AU3: 59 | AZ3: naveen.lagishetty | BA3: 8
A4: naveen.lagishetty | B4: 45208 | C4: Testing | D4: 1 | E4: 1 | G4: Total Units to be produced | H4: {=Project[No. of Units in URL Sheet]} -> 35 | K4: kumar.reddy | L4: 15 | M4: 75 | N4: 70 | O4: 93.333333 | Q4: manisha.prakash | R4: 22 | S4: 85 | U4: 0 | W4: naveen.lagishetty | Z4: 8 | AA4: 1 | AB4: 1 | AC4: 10 | AL4: (blank) | AO4: (blank) | AS4: naveen.lagishetty | AT4: 13 | AU4: 13 | AZ4: irfan shaikh | BA4: 1
A5: harshada.morje | B5: 45208 | C5: Meeting | D5: 0.5 | E5: 0 | G5: Delivery | H5: {=Project[Estimated Delivery Date]} -> 45219 | K5: irfan.shaikh | L5: 1 | M5: 5 | O5: 0 | Q5: Grand Total | R5: 91 | S5: 100 | U5: 0 | W5: irfan shaikh | AL5: naveen.lagishetty | AM5: 45 | AO5: naveen.lagishetty | AP5: 45 | AS5: kumar.reddy | AT5: 15 | AU5: 15 | AZ5: Kumar.reddy | BA5: 6
A6: harshada.morje | B6: 45208 | C6: Support | D6: 0.5 | E6: 10 | G6: Testing - To Be Approved | H6: =COUNTIF(Final_Report[Status],"To Be Approved") -> 0 | K6: nachiket.kulawade | L6: 2 | M6: 10 | O6: 0 | W6: Kumar.reddy | Y6: 2 | Z6: 3 | AA6: 5 | AB6: 5 | AC6: 15 | AL6: irfan shaikh | AM6: 8 | AO6: irfan shaikh | AP6: 8 | AS6: irfan.shaikh | AT6: 1 | AU6: 1 | AZ6: harshada.morje
A7: kumar.reddy | B7: 45209 | C7: Testing | D7: 5 | E7: 5 | G7: Reporting - To Be Approved | H7: =COUNTIF(Final_Report[Finalized],"To Be Approved") -> 2 | K7: harshada.morje | L7: 1 | M7: 5 | O7: 0 | W7: harshada.morje | AA7: 2 | AC7: 2 | AL7: Kumar.reddy | AM7: 21 | AO7: Kumar.reddy | AP7: 21 | AS7: nachiket.kulawade | AT7: 2 | AU7: 2 | AZ7: nachiket.kulawade
A8: kumar.reddy | B8: 45210 | C8: Testing | D8: 3 | E8: 3 | K8: Grand Total | L8: 91 | M8: 145 | N8: 120 | O8: 82.758621 | W8: nachiket.kulawade | AL8: harshada.morje | AM8: 14 | AO8: harshada.morje | AP8: 15 | AS8: harshada.morje | AT8: 1 | AU8: 1 | AZ8: Grand Total | BA8: 15
A9: irfan.shaikh | B9: 45210 | C9: Testing | D9: 3 | E9: 2 | W9: Grand Total | Y9: 2 | Z9: 11 | AA9: 8 | AB9: 6 | AC9: 27 | AL9: nachiket.kulawade | AM9: 3 | AO9: nachiket.kulawade | AP9: 3 | AS9: Grand Total | AT9: 91 | AU9: 91
A10: naveen.lagishetty | B10: 45209 | C10: Meeting | D10: 0.5 | E10: 1 | AL10: Grand Total | AM10: 91 | AO10: Grand Total | AP10: 92
A11: naveen.lagishetty | B11: 45209 | C11: Testing | D11: 4 | E11: 6
A12: naveen.lagishetty | B12: 45210 | C12: Meeting | D12: 0.5 | E12: 1
A13: naveen.lagishetty | B13: 45210 | C13: Report | D13: 2 | E13: 4 | AM13: Issue Complexity
A14: harshada.morje | B14: 45210 | C14: Meeting | D14: 0.5 | E14: 0 | AM14: #N/A | AN14: (blank) | AO14: Grand Total
A15: naveen.lagishetty | B15: 45211 | C15: Report | D15: 3 | E15: 5 | AL15: Count of Issue Name | AM15: 91 | AO15: 91
A16: kumar.reddy | B16: 45211 | C16: Report | D16: 2 | E16: 6 | G16: Units | H16: Column Labels
A17: prerna.rane | B17: 45212 | C17: Testing | D17: 2 | E17: 2 | G17: Row Labels | H17: 45208 | I17: 45209 | J17: 45210 | K17: 45211 | L17: 45212 | M17: 45215 | N17: 45216 | O17: 45218 | P17: Grand Total
A18: prerna.rane | B18: 45212 | C18: Testing | D18: 1 | E18: 0 | G18: Testing | H18: 10 | I18: 11 | J18: 5 | K18: 3 | L18: 2 | M18: 5 | N18: 2 | O18: 4 | P18: 42
A19: manasi.varma | B19: 45212 | C19: Testing | D19: 0.5 | E19: 0 | G19: kumar.reddy | H19: 3 | I19: 5 | J19: 3 | M19: 1 | P19: 12
A20: harshada.morje | B20: 45211 | C20: Testing | D20: 3 | E20: 3 | G20: naveen.lagishetty | H20: 7 | I20: 6 | P20: 13
A21: kumar.reddy | B21: 45215 | C21: Testing | D21: 1 | E21: 1 | G21: harshada.morje | K21: 3 | M21: 4 | P21: 7
A22: kumar.reddy | B22: 45215 | C22: Report | D22: 2.5 | E22: 8 | G22: irfan.shaikh | J22: 2 | P22: 2
A23: manasi.varma | B23: 45215 | C23: Support | D23: 0.5 | E23: 2 | G23: prerna.rane | L23: 2 | P23: 2
A24: manasi.varma | B24: 45215 | C24: Testing | D24: 2 | E24: 0 | G24: manasi.varma | L24: 0 | M24: 0 | O24: 0 | P24: 0
A25: harshada.morje | B25: 45215 | C25: Testing | D25: 4 | E25: 4 | G25: dilip.dharia | N25: 2 | O25: 4 | P25: 6
A26: manasi.varma | B26: 45216 | C26: QA | D26: 1 | E26: 3 | G26: Meeting | H26: 0 | I26: 1 | J26: 1 | O26: 0 | P26: 2
A27: dilip.dharia | B27: 45216 | C27: Testing | D27: 2 | E27: 2 | G27: naveen.lagishetty | I27: 1 | J27: 1 | P27: 2
A28: dilip.dharia | B28: 45216 | C28: Testing | D28: 1 | E28: 0 | G28: harshada.morje | H28: 0 | J28: 0 | P28: 0
A29: kumar.reddy | B29: 45218 | C29: Support | D29: 0.5 | G29: manisha.prakash | O29: 0 | P29: 0
A30: dilip.dharia | B30: 45218 | C30: Support | D30: 3 | E30: 35 | G30: Support | H30: 10 | M30: 2 | O30: 37 | P30: 49
A31: dilip.dharia | B31: 45218 | C31: Testing | D31: 4.75 | E31: 4 | G31: kumar.reddy
A32: manasi.varma | B32: 45218 | C32: Testing | D32: 3.5 | E32: 0 | G32: harshada.morje | H32: 10 | P32: 10
A33: manasi.varma | B33: 45218 | C33: Support | D33: 0.75 | E33: 2 | G33: manasi.varma | M33: 2 | O33: 2 | P33: 4
A34: manisha.prakash | B34: 45218 | C34: QA | D34: 2.75 | E34: 10 | G34: dilip.dharia | O34: 35 | P34: 35
A35: manisha.prakash | B35: 45218 | C35: Meeting | D35: 0.5 | E35: 0 | G35: Report | J35: 4 | K35: 11 | M35: 8 | P35: 23
G36: kumar.reddy | K36: 6 | M36: 8 | P36: 14
G37: naveen.lagishetty | J37: 4 | K37: 5 | P37: 9
G38: QA | N38: 3 | O38: 10 | P38: 13
G39: manasi.varma | N39: 3 | P39: 3
G40: manisha.prakash | O40: 10 | P40: 10
...

Sheet URL
A1: Sr. No. | B1: Page Name | C1: URL | D1: Type | E1: Notes | F1: Browser | G1: Screen Reader | H1: Magnification | I1: Speech Recognition | J1: Accessibility Settings | K1: Mobile Tablet | L1: FT Tester | M1: AT Tester | N1: FT QA | O1: AT QA | P1: QA | Q1: QA2
A2: P1 | B2: Left Navigation | D2: Component | E2: Instructor account with Student View | F2: Chrome | G2: JAWS 2022 | K2: Android Tablet (Nachiket) | L2: Naveen | P2: Manasi
A3: P2 | B3: Course Home - Calendar | D3: Page | E3: Instructor account with Student View | F3: Chrome | G3: JAWS 2022 | H3: Yes | K3: Android Tablet (Nachiket) | L3: Naveen | P3: Manasi
A4: P3 | B4: Student Success Hub | D4: Component | E4: Instructor account with Student View | F4: Chrome | G4: JAWS 2022 | K4: Android Tablet (Nachiket) | L4: Naveen | P4: Manasi
A5: P4 | B5: MyLab Tour for students | D5: Page | E5: Instructor account with Student View | F5: Chrome | G5: JAWS 2022 | H5: Yes | K5: Android Tablet (Nachiket) | L5: Naveen | P5: Manasi
A6: P5 | B6: Dynamic Study Modules | D6: Component | E6: Instructor account with Student View | F6: Chrome | G6: JAWS 2022 | K6: Android Tablet (Nachiket) | L6: Naveen | P6: Manasi
A7: P6 | B7: Multimedia Library Mainpage | D7: Page | E7: Instructor account with Student View | F7: Chrome | G7: JAWS 2022 | K7: Android Tablet (Nachiket) | L7: Naveen | P7: Manasi
A8: P7 | B8: Print Offers | D8: Component | E8: Instructor account with Student View | F8: Chrome | G8: JAWS 2022 | K8: Android Tablet (Nachiket) | L8: Naveen | P8: Manasi
A9: P8 | B9: eTextbook | D9: Page | E9: Instructor account with Student View | F9: Chrome | G9: JAWS 2022 | K9: Android Tablet (Nachiket) | L9: Naveen | P9: Manasi
A10: P9 | B10: Course Home - Document Sharing | C10: https://mylabmastering.pearson.com/?courseId=12530108&key=1540223697657138739132023#/DocSharing/813763a3-21c6-41d5-8e84-98acc6a32e05 | D10: Component | E10: Instructor account with Student View | F10: Chrome | G10: JAWS 2022 | K10: Android Tablet (Nachiket) | L10: Irfan | M10: Dilip | P10: Manasi
A11: P10 | B11: Accessibility Information | C11: https://mylabmastering.pearson.com/?courseId=12530108&key=1540223697657138739132023#/ | D11: Page | E11: Instructor account with Student View | F11: Chrome | G11: JAWS 2022 | K11: Android Tablet (Nachiket) | L11: Irfan | M11: Dilip | P11: Manasi
A12: P11 | B12: Student To-do list | C12: https://mylabmastering.pearson.com/?courseId=12530108&key=620406497315419132023#/ | D12: Page | E12: Student Account | F12: Chrome | G12: JAWS 2022 | K12: Android Tablet (Nachiket) | L12: Irfan | M12: Dilip | P12: Manasi
A13: P12 | B13: Chapter 9 Homework: Question 1 | D13: Component | E13: Student Account | F13: Chrome | G13: JAWS 2022 | K13: Android Tablet (Nachiket) | L13: Irfan | M13: Dilip | P13: Manasi
A14: P13 | B14: Chapter 9 Homework: Question 5 | D14: Component | E14: Student Account | F14: FF | G14: NVDA | K14: Android Tablet (Nachiket) | L14: Naveen | P14: Manasi
A15: P14 | B15: Video Assignment Page | D15: Page | E15: Student Account | F15: FF | G15: NVDA | K15: Android Tablet (Nachiket) | L15: Kumar | P15: Manasi
A16: P15 | B16: Video: Question 1 | D16: Component | E16: Student Account | F16: FF | G16: NVDA | K16: Android Tablet (Nachiket) | L16: Kumar | P16: Manasi
A17: P16 | B17: Video Quiz Summary | D17: Component | F17: FF | G17: NVDA | K17: iPad (Harshada) | L17: Kumar | P17: Manasi
A18: P17 | B18: Question 1 | D18: Page | F18: FF | G18: NVDA | K18: Android Tablet (Nachiket) | L18: Kumar | P18: Manasi
A19: P18 | B19: Question 1 | D19: Component | F19: FF | G19: NVDA | L19: Kumar | P19: Manasi
A20: P19 | B20: Case Study Library Mainpage | D20: Page | F20: FF | G20: NVDA | K20: Android Tablet (Nachiket) | L20: Kumar | P20: Manasi
A21: P20 | B21: Case Study - Brief | D21: Page | F21: FF | G21: NVDA | K21: iPad (Harshada) | L21: Kumar | P21: Manasi
A22: P21 | B22: Case Study - Questions | D22: Page | F22: FF | G22: NVDA | K22: iPad (Harshada) | L22: Kumar | P22: Manasi
A23: P22 | B23: Podcast Assignment Mainpage | D23: Page | F23: FF | G23: NVDA | K23: iPad (Harshada) | L23: Kumar | P23: Manasi
A24: P23 | B24: Question 1 | D24: Component | F24: FF | G24: NVDA | K24: iPad (Harshada) | L24: Kumar | P24: Manasi
A25: P24 | B25: Podcast Quiz Summary | D25: Component | F25: FF | G25: NVDA | K25: iPad (Harshada) | L25: Kumar | P25: Manasi
A26: P25 | B26: Take a Quiz test | D26: Page | F26: Mac | G26: VoiceOver | K26: iPad (Harshada) | L26: Harshada | P26: Manasi
A27: P26 | B27: Start Quiz Page | D27: Component | F27: Mac | G27: VoiceOver | K27: iPad (Harshada) | L27: Harshada | P27: Manasi
A28: P27 | B28: Question 1 | D28: Component | F28: Mac | G28: VoiceOver | K28: iPad (Harshada) | L28: Harshada | P28: Manasi
A29: P28 | B29: Quiz Summary | D29: Page | F29: Mac | G29: VoiceOver | K29: iPad (Harshada) | L29: Harshada | P29: Manasi
A30: P29 | B30: Study Plan Recommendations | D30: Page | F30: Mac | G30: VoiceOver | K30: iPad (Harshada) | L30: Harshada | P30: Manasi
A31: P30 | B31: Practice Define marketing and outline the steps in the marketing process: Question 1 | D31: Component | F31: Mac | G31: VoiceOver | K31: iPad (Harshada) | L31: Harshada | P31: Manasi
... A35: P34 | B35: Study Plan All Chapters | D35: Page | F35: Mac | G35: VoiceOver | K35: iPad (Harshada) | L35: Harshada | P35: Manasi
A36: P35 | B36: Student Gradebook Results Page | D36: Page | E36: Student Account | F36: Mac | G36: VoiceOver | K36: iPad (Harshada) | L36: Harshada | P36: Manasi
B37: Column Labels
B38: (blank) | C38: No QA Needed | D38: Delete | E38: approved | F38: Grand Total
A39: Sum of Issue Name | C39: 0 | D39: 0 | E39: 0 | F39: 0

Sheet Final Report
A1: Page | B1: Page Name | C1: URL Link | D1: Type of Issue | E1: Issue Name | F1: Comments | G1: Chrome/JAWS | H1: FF/NVDA | I1: Chrome/NVDA | J1: Mac/Safari/VO | K1: Mac/Chrome/VO | L1: iOS/VO | M1: Android/Talkback | N1: ZoomText | O1: Dragon | P1: Issue Tested By | Q1: Status | R1: Testing - Reviewed By | S1: Move to Report | T1: Summary | U1: Issue Description | V1: FinaIized - Issue Description | W1: Code Snippet | X1: FinaIized - Code Snippet | Y1: Expected Result | Z1: FinaIized - Expected Result | AA1: Rationale | AB1: Recommendation | AC1: FinaIized - Recommendation | AD1: Steps to Reproduce Start | AE1: Steps to Reproduce | AF1: FinaIized - Steps to Reproduce | AG1: WCAG 2.1 Conformance Level | AH1: WCAG 2.1 Success Criteria | AI1: ScreenShot Name | AJ1: Priority | AK1: Tested On | AL1: Components | AM1: Labels | AN1: Severity | AO1: Issue Written By | AP1: Self QC | AQ1: Writing Score | AR1: Tester's Comment | AS1: BB Self QC | AT1: Reporting - Reviewed By | AU1: Reviewers comment | AV1: Issue Level | AW1: Self QC QA | AX1: Finalized | AY1: BB Self QC QA | AZ1: Regression Status | BA1: Uploading Status | BB1: Uploading comment | BC1: Issue Complexity | BD1: Client Feedback | BE1: Client Feedback Level
A2: P1 | B2: =VLOOKUP(A2,URL[],2,0) -> Left Navigation | C2: =VLOOKUP(A2,URL[],3,0) -> 0 | D2: ARIA | E2: ARIA attribute defined inappropriately | F2: Left navigation buttons aria-expand/collapse functionality is unclear - Known issue - ACDS-265656, ACDS-262925 known check done valid- dilip | G2: Applicable | H2: Applicable | I2: Applicable | P2: naveen.lagishetty | Q2: No QA Needed | R2: 0 | S2: No | T2: =IF(Final_Report[[#This Row],[Move to Report]]="Yes",VLOOKUP(E2,IssueVariable[],3,0),"N/A") -> N/A | U2: =IF(Final_Report[[#This Row],[Move to Report]]="Yes",VLOOKUP(E2,IssueVariable[],4,0),"N/A") -> N/A | V2: =Final_Report[[#This Row],[Issue Description]] -> N/A | X2: =Final_Report[[#This Row],[Code Snippet]] -> 0 | Y2: =IF(Final_Report[[#This Row],[Move to Report]]="Yes",VLOOKUP(E2,IssueVariable[],5,0),"N/A") -> N/A | Z2: =Final_Report[[#This Row],[Expected Result]] -> N/A | AA2: =IF(Final_Report[[#This Row],[Move to Report]]="Yes",VLOOKUP(E2,IssueVariable[],6,0),"N/A") -> N/A | AB2: =IF(Final_Report[[#This Row],[Move to Report]]="Yes",VLOOKUP(E2,IssueVariable[],7,0),"N/A") -> N/A | AC2: =Final_Report[[#This Row],[Recommendation]] -> N/A | AE2: =IF(Final_Report[[#This Row],[Move to Report]]="Yes",VLOOKUP(E2,IssueVariable[],8,0),"N/A") -> N/A | AF2: =Final_Report[[#This Row],[Steps to Reproduce]] -> N/A | AG2: =IF(Final_Report[[#This Row],[Move to Report]]="Yes",VLOOKUP(E2,IssueVariable[],9,0),"N/A") -> N/A | AH2: =IF(Final_Report[[#This Row],[Move to Report]]="Yes",VLOOKUP(E2,IssueVariable[],10,0),"N/A") -> N/A | AK2: {=Table95[Tested on]} -> Windows: 11 MAC OS: 12 iOS: 15 Android OS: 10 | AL2: {=_xlfn.TEXTJOIN(", ",TRUE,_xlfn.UNIQUE(TRIM(MID(SUBSTITUTE((Final_Report[[#This Row],[WCAG 2.1 Success Criteria]] &_xlfn.CONCAT(" (Level ") &Final_Report[[#This Row],[WCAG 2.1 Conformance Level]] &_xlfn.CONCAT("), ") &IF(Final_Report[[#This Row],[Chrome/JAWS]]="Applicable","Windows_11, Chrome, JAWS, ", " ") &IF(Final_Report[[#This Row],[FF/NVDA]]="Applicable", "Windows_11, Firefox, NVDA, ", " ") &IF(Final_Report[[#This Row],[Chrome/NVDA]]="Applicable", "Windows_11, Chrome, NVDA, ", " ") &IF(Final_Report[[#This Row],[iOS/VO]]="Applicable", "iOS Tablet, VoiceOver, ", " ") &IF(Final_Report[[#This Row],[Mac/Safari/VO]]="Applicable", "macOS_12, Safari, VoiceOver, ", " ") &IF(Final_Report[[#This Row],[Mac/Chrome/VO]]="Applicable", "macOS_12, Chrome, VoiceOver, ", " ") &IF(Final_Report[[#This Row],[Android/Talkback]]="Applicable", "TalkBack, Android Tablet", " ") ) &", " &IF(ISERROR(FIND("iOS 13",INDEX(Keyword[Component Keyword],MATCH(TRUE,INDEX((Keyword[Component Keyword]<>0),0),0)))=FALSE),INDEX(Keyword[Component Keyword],MATCH(TRUE,INDEX((Keyword[Component Keyword]<>0),0),0)),SUBSTITUTE(INDEX(Keyword[Component Keyword],MATCH(TRUE,INDEX((Keyword[Component Keyword]<>0),0),0)),"iOS 13","iOS")),",",REPT(" ",999)),(ROW($AAN$1:INDEX($AAX:$AAX,LEN((Final_Report[[#This Row],[WCAG 2.1 Success Criteria]] &_xlfn.CONCAT(" (Level ") &Final_Report[[#This Row],[WCAG 2.1 Conformance Level]] &_xlfn.CONCAT("), ") &IF(Final_Report[[#This Row],[Chrome/JAWS]]="Applicable","Windows_11, Chrome, JAWS, ", " ") &IF(Final_Report[[#This Row],[FF/NVDA]]="Applicable", "Windows_11, Firefox, NVDA, ", " ") &IF(Final_Report[[#This Row],[Chrome/NVDA]]="Applicable", "Windows_11, Chrome, NVDA, ", " ") &IF(Final_Report[[#This Row],[iOS/VO]]="Applicable", "iOS Tablet, VoiceOver, ", " ") &IF(Final_Report[[#This Row],[Mac/Safari/VO]]="Applicable", "macOS_12, Safari, VoiceOver, ", " ") &IF(Final_Report[[#This Row],[Mac/Chrome/VO]]="Applicable", "macOS_12, Chrome, VoiceOver, ", " ") &IF(Final_Report[[#This Row],[Android/Talkback]]="Applicable", "TalkBack, Android Tablet", " ") ) &", " &IF(ISERROR(FIND("iOS 13",INDEX(Keyword[Component Keyword],MATCH(TRUE,INDEX((Keyword[Component Keyword]<>0),0),0)))=FALSE),INDEX(Keyword[Component Keyword],MATCH(TRUE,INDEX((Keyword[Component Keyword]<>0),0),0)),SUBSTITUTE(INDEX(Keyword[Component Keyword],MATCH(TRUE,INDEX((Keyword[Component Keyword]<>0),0),0)),"iOS 13","iOS")))-LEN(SUBSTITUTE((Final_Report[[#This Row],[WCAG 2.1 Success Criteria]] &_xlfn.CONCAT(" (Level ") &Final_Report[[#This Row],[WCAG 2.1 Conformance Level]] &_xlfn.CONCAT("), ") &IF(Final_Report[[#This Row],[Chrome/JAWS]]="Applicable","Windows_11, Chrome, JAWS, ", " ") &IF(Final_Report[[#This Row],[FF/NVDA]]="Applicable", "Windows_11, Firefox, NVDA, ", " ") &IF(Final_Report[[#This Row],[Chrome/NVDA]]="Applicable", "Windows_11, Chrome, NVDA, ", " ") &IF(Final_Report[[#This Row],[iOS/VO]]="Applicable", "iOS Tablet, VoiceOver, ", " ") &IF(Final_Report[[#This Row],[Mac/Safari/VO]]="Applicable", "macOS_12, Safari, VoiceOver, ", " ") &IF(Final_Report[[#This Row],[Mac/Chrome/VO]]="Applicable", "macOS_12, Chrome, VoiceOver, ", " ") &IF(Final_Report[[#This Row],[Android/Talkback]]="Applicable", "TalkBack, Android Tablet", " ") ) &", " &IF(ISERROR(FIND("iOS 13",INDEX(Keyword[Component Keyword],MATCH(TRUE,INDEX((Keyword[Component Keyword]<>0),0),0)))=FALSE),INDEX(Keyword[Component Keyword],MATCH(TRUE,INDEX((Keyword[Component Keyword]<>0),0),0)),SUBSTITUTE(INDEX(Keyword[Component Keyword],MATCH(TRUE,INDEX((Keyword[Component Keyword]<>0),0),0)),"iOS 13","iOS")),",",""))+1))-1)*999+1,999))))} -> N/A (Level N/A), Windows_11, Chrome, JAWS, Firefox, NVDA, Accessibility, Audit, Marketing, MLM-XL, MLVISION, MyLab, US, VPAT | AM2: {=CONCATENATE(LEFT(AH2, SEARCH(" ", AH2) -1),", ",Labels[Labels])} -> #VALUE! | AN2: =IF(AJ2="Blocker","1 - Critical - showstopper",IF(AJ2="Critical","1 - Critical - showstopper",IF(AJ2="Major","1 - Critical - showstopper",IF(AJ2="Minor","3 - Medium - minor functionality broken",IF(AJ2="Trivial","4 - Low - cosmetic or usability"))))) -> FALSE | BC2: =VLOOKUP('Final Report'!D2,'Issue Variable'!A:N,11,FALSE) -> #N/A
A3: P1 | B3: =VLOOKUP(A3,URL[],2,0) -> Left Navigation | C3: =VLOOKUP(A3,URL[],3,0) -> 0 | D3: Images | E3: No text equivalent for SVG image | F3: Left navigation "Educator Hub->Instructor Resources" when user acitvate it opens a page in new tab - Known issue - ACDS-251421 known check done valid- dilip | G3: Applicable | H3: Applicable | I3: Applicable | P3: naveen.lagishetty | Q3: No QA Needed | S3: No | T3: =IF(Final_Report[[#This Row],[Move to Report]]="Yes",VLOOKUP(E3,IssueVariable[],3,0),"N/A") -> N/A | U3: =IF(Final_Report[[#This Row],[Move to Report]]="Yes",VLOOKUP(E3,IssueVariable[],4,0),"N/A") -> N/A | V3: =Final_Report[[#This Row],[Issue Description]] -> N/A | X3: =Final_Report[[#This Row],[Code Snippet]] -> 0 | Y3: =IF(Final_Report[[#This Row],[Move to Report]]="Yes",VLOOKUP(E3,IssueVariable[],5,0),"N/A") -> N/A | Z3: =Final_Report[[#This Row],[Expected Result]] -> N/A | AA3: =IF(Final_Report[[#This Row],[Move to Report]]="Yes",VLOOKUP(E3,IssueVariable[],6,0),"N/A") -> N/A | AB3: =IF(Final_Report[[#This Row],[Move to Report]]="Yes",VLOOKUP(E3,IssueVariable[],7,0),"N/A") -> N/A | AC3: =Final_Report[[#This Row],[Recommendation]] -> N/A | AE3: =IF(Final_Report[[#This Row],[Move to Report]]="Yes",VLOOKUP(E3,IssueVariable[],8,0),"N/A") -> N/A | AF3: =Final_Report[[#This Row],[Steps to Reproduce]] -> N/A | AG3: =IF(Final_Report[[#This Row],[Move to Report]]="Yes",VLOOKUP(E3,IssueVariable[],9,0),"N/A") -> N/A | AH3: =IF(Final_Report[[#This Row],[Move to Report]]="Yes",VLOOKUP(E3,IssueVariable[],10,0),"N/A") -> N/A | AK3: {=Table95[Tested on]} -> Windows: 11 MAC OS: 12 iOS: 15 Android OS: 10 | AL3: {=_xlfn.TEXTJOIN(", ",TRUE,_xlfn.UNIQUE(TRIM(MID(SUBSTITUTE((Final_Report[[#This Row],[WCAG 2.1 Success Criteria]] &_xlfn.CONCAT(" (Level ") &Final_Report[[#This Row],[WCAG 2.1 Conformance Level]] &_xlfn.CONCAT("), ") &IF(Final_Report[[#This Row],[Chrome/JAWS]]="Applicable","Windows_11, Chrome, JAWS, ", " ") &IF(Final_Report[[#This Row],[FF/NVDA]]="Applicable", "Windows_11, Firefox, NVDA, ", " ") &IF(Final_Report[[#This Row],[Chrome/NVDA]]="Applicable", "Windows_11, Chrome, NVDA, ", " ") &IF(Final_Report[[#This Row],[iOS/VO]]="Applicable", "iOS Tablet, VoiceOver, ", " ") &IF(Final_Report[[#This Row],[Mac/Safari/VO]]="Applicable", "macOS_12, Safari, VoiceOver, ", " ") &IF(Final_Report[[#This Row],[Mac/Chrome/VO]]="Applicable", "macOS_12, Chrome, VoiceOver, ", " ") &IF(Final_Report[[#This Row],[Android/Talkback]]="Applicable", "TalkBack, Android Tablet", " ") ) &", " &IF(ISERROR(FIND("iOS 13",INDEX(Keyword[Component Keyword],MATCH(TRUE,INDEX((Keyword[Component Keyword]<>0),0),0)))=FALSE),INDEX(Keyword[Component Keyword],MATCH(TRUE,INDEX((Keyword[Component Keyword]<>0),0),0)),SUBSTITUTE(INDEX(Keyword[Component Keyword],MATCH(TRUE,INDEX((Keyword[Component Keyword]<>0),0),0)),"iOS 13","iOS")),",",REPT(" ",999)),(ROW($AAN$1:INDEX($AAX:$AAX,LEN((Final_Report[[#This Row],[WCAG 2.1 Success Criteria]] &_xlfn.CONCAT(" (Level ") &Final_Report[[#This Row],[WCAG 2.1 Conformance Level]] &_xlfn.CONCAT("), ") &IF(Final_Report[[#This Row],[Chrome/JAWS]]="Applicable","Windows_11, Chrome, JAWS, ", " ") &IF(Final_Report[[#This Row],[FF/NVDA]]="Applicable", "Windows_11, Firefox, NVDA, ", " ") &IF(Final_Report[[#This Row],[Chrome/NVDA]]="Applicable", "Windows_11, Chrome, NVDA, ", " ") &IF(Final_Report[[#This Row],[iOS/VO]]="Applicable", "iOS Tablet, VoiceOver, ", " ") &IF(Final_Report[[#This Row],[Mac/Safari/VO]]="Applicable", "macOS_12, Safari, VoiceOver, ", " ") &IF(Final_Report[[#This Row],[Mac/Chrome/VO]]="Applicable", "macOS_12, Chrome, VoiceOver, ", " ") &IF(Final_Report[[#This Row],[Android/Talkback]]="Applicable", "TalkBack, Android Tablet", " ") ) &", " &IF(ISERROR(FIND("iOS 13",INDEX(Keyword[Component Keyword],MATCH(TRUE,INDEX((Keyword[Component Keyword]<>0),0),0)))=FALSE),INDEX(Keyword[Component Keyword],MATCH(TRUE,INDEX((Keyword[Component Keyword]<>0),0),0)),SUBSTITUTE(INDEX(Keyword[Component Keyword],MATCH(TRUE,INDEX((Keyword[Component Keyword]<>0),0),0)),"iOS 13","iOS")))-LEN(SUBSTITUTE((Final_Report[[#This Row],[WCAG 2.1 Success Criteria]] &_xlfn.CONCAT(" (Level ") &Final_Report[[#This Row],[WCAG 2.1 Conformance Level]] &_xlfn.CONCAT("), ") &IF(Final_Report[[#This Row],[Chrome/JAWS]]="Applicable","Windows_11, Chrome, JAWS, ", " ") &IF(Final_Report[[#This Row],[FF/NVDA]]="Applicable", "Windows_11, Firefox, NVDA, ", " ") &IF(Final_Report[[#This Row],[Chrome/NVDA]]="Applicable", "Windows_11, Chrome, NVDA, ", " ") &IF(Final_Report[[#This Row],[iOS/VO]]="Applicable", "iOS Tablet, VoiceOver, ", " ") &IF(Final_Report[[#This Row],[Mac/Safari/VO]]="Applicable", "macOS_12, Safari, VoiceOver, ", " ") &IF(Final_Report[[#This Row],[Mac/Chrome/VO]]="Applicable", "macOS_12, Chrome, VoiceOver, ", " ") &IF(Final_Report[[#This Row],[Android/Talkback]]="Applicable", "TalkBack, Android Tablet", " ") ) &", " &IF(ISERROR(FIND("iOS 13",INDEX(Keyword[Component Keyword],MATCH(TRUE,INDEX((Keyword[Component Keyword]<>0),0),0)))=FALSE),INDEX(Keyword[Component Keyword],MATCH(TRUE,INDEX((Keyword[Component Keyword]<>0),0),0)),SUBSTITUTE(INDEX(Keyword[Component Keyword],MATCH(TRUE,INDEX((Keyword[Component Keyword]<>0),0),0)),"iOS 13","iOS")),",",""))+1))-1)*999+1,999))))} -> N/A (Level N/A), Windows_11, Chrome, JAWS, Firefox, NVDA, Accessibility, Audit, Marketing, MLM-XL, MLVISION, MyLab, US, VPAT | AM3: {=CONCATENATE(LEFT(AH3, SEARCH(" ", AH3) -1),", ",Labels[Labels])} -> #VALUE! | AN3: =IF(AJ3="Blocker","1 - Critical - showstopper",IF(AJ3="Critical","1 - Critical - showstopper",IF(AJ3="Major","1 - Critical - showstopper",IF(AJ3="Minor","3 - Medium - minor functionality broken",IF(AJ3="Trivial","4 - Low - cosmetic or usability"))))) -> FALSE | BC3: =VLOOKUP('Final Report'!D3,'Issue Variable'!A:N,11,FALSE) -> #N/A
A4: P1 | B4: =VLOOKUP(A4,URL[],2,0) -> Left Navigation | C4: =VLOOKUP(A4,URL[],3,0) -> 0 | D4: Keyboard | E4: Missing Keyboard Support for Button | F4: Left navigation elements has role="button" so it should work with space and enter key but it works with only enter key. | G4: Applicable | I4: Applicable | P4: naveen.lagishetty | Q4: No QA Needed | S4: No | T4: =IF(Final_Report[[#This Row],[Move to Report]]="Yes",VLOOKUP(E4,IssueVariable[],3,0),"N/A") -> N/A | U4: =IF(Final_Report[[#This Row],[Move to Report]]="Yes",VLOOKUP(E4,IssueVariable[],4,0),"N/A") -> N/A | V4: =Final_Report[[#This Row],[Issue Description]] -> N/A | X4: =Final_Report[[#This Row],[Code Snippet]] -> 0 | Y4: =IF(Final_Report[[#This Row],[Move to Report]]="Yes",VLOOKUP(E4,IssueVariable[],5,0),"N/A") -> N/A | Z4: =Final_Report[[#This Row],[Expected Result]] -> N/A | AA4: =IF(Final_Report[[#This Row],[Move to Report]]="Yes",VLOOKUP(E4,IssueVariable[],6,0),"N/A") -> N/A | AB4: =IF(Final_Report[[#This Row],[Move to Report]]="Yes",VLOOKUP(E4,IssueVariable[],7,0),"N/A") -> N/A | AC4: =Final_Report[[#This Row],[Recommendation]] -> N/A | AE4: =IF(Final_Report[[#This Row],[Move to Report]]="Yes",VLOOKUP(E4,IssueVariable[],8,0),"N/A") -> N/A | AF4: =Final_Report[[#This Row],[Steps to Reproduce]] -> N/A | AG4: =IF(Final_Report[[#This Row],[Move to Report]]="Yes",VLOOKUP(E4,IssueVariable[],9,0),"N/A") -> N/A | AH4: =IF(Final_Report[[#This Row],[Move to Report]]="Yes",VLOOKUP(E4,IssueVariable[],10,0),"N/A") -> N/A | AK4: {=Table95[Tested on]} -> Windows: 11 MAC OS: 12 iOS: 15 Android OS: 10 | AL4: {=_xlfn.TEXTJOIN(", ",TRUE,_xlfn.UNIQUE(TRIM(MID(SUBSTITUTE((Final_Report[[#This Row],[WCAG 2.1 Success Criteria]] &_xlfn.CONCAT(" (Level ") &Final_Report[[#This Row],[WCAG 2.1 Conformance Level]] &_xlfn.CONCAT("), ") &IF(Final_Report[[#This Row],[Chrome/JAWS]]="Applicable","Windows_11, Chrome, JAWS, ", " ") &IF(Final_Report[[#This Row],[FF/NVDA]]="Applicable", "Windows_11, Firefox, NVDA, ", " ") &IF(Final_Report[[#This Row],[Chrome/NVDA]]="Applicable", "Windows_11, Chrome, NVDA, ", " ") &IF(Final_Report[[#This Row],[iOS/VO]]="Applicable", "iOS Tablet, VoiceOver, ", " ") &IF(Final_Report[[#This Row],[Mac/Safari/VO]]="Applicable", "macOS_12, Safari, VoiceOver, ", " ") &IF(Final_Report[[#This Row],[Mac/Chrome/VO]]="Applicable", "macOS_12, Chrome, VoiceOver, ", " ") &IF(Final_Report[[#This Row],[Android/Talkback]]="Applicable", "TalkBack, Android Tablet", " ") ) &", " &IF(ISERROR(FIND("iOS 13",INDEX(Keyword[Component Keyword],MATCH(TRUE,INDEX((Keyword[Component Keyword]<>0),0),0)))=FALSE),INDEX(Keyword[Component Keyword],MATCH(TRUE,INDEX((Keyword[Component Keyword]<>0),0),0)),SUBSTITUTE(INDEX(Keyword[Component Keyword],MATCH(TRUE,INDEX((Keyword[Component Keyword]<>0),0),0)),"iOS 13","iOS")),",",REPT(" ",999)),(ROW($AAN$1:INDEX($AAX:$AAX,LEN((Final_Report[[#This Row],[WCAG 2.1 Success Criteria]] &_xlfn.CONCAT(" (Level ") &Final_Report[[#This Row],[WCAG 2.1 Conformance Level]] &_xlfn.CONCAT("), ") &IF(Final_Report[[#This Row],[Chrome/JAWS]]="Applicable","Windows_11, Chrome, JAWS, ", " ") &IF(Final_Report[[#This Row],[FF/NVDA]]="Applicable", "Windows_11, Firefox, NVDA, ", " ") &IF(Final_Report[[#This Row],[Chrome/NVDA]]="Applicable", "Windows_11, Chrome, NVDA, ", " ") &IF(Final_Report[[#This Row],[iOS/VO]]="Applicable", "iOS Tablet, VoiceOver, ", " ") &IF(Final_Report[[#This Row],[Mac/Safari/VO]]="Applicable", "macOS_12, Safari, VoiceOver, ", " ") &IF(Final_Report[[#This Row],[Mac/Chrome/VO]]="Applicable", "macOS_12, Chrome, VoiceOver, ", " ") &IF(Final_Report[[#This Row],[Android/Talkback]]="Applicable", "TalkBack, Android Tablet", " ") ) &", " &IF(ISERROR(FIND("iOS 13",INDEX(Keyword[Component Keyword],MATCH(TRUE,INDEX((Keyword[Component Keyword]<>0),0),0)))=FALSE),INDEX(Keyword[Component Keyword],MATCH(TRUE,INDEX((Keyword[Component Keyword]<>0),0),0)),SUBSTITUTE(INDEX(Keyword[Component Keyword],MATCH(TRUE,INDEX((Keyword[Component Keyword]<>0),0),0)),"iOS 13","iOS")))-LEN(SUBSTITUTE((Final_Report[[#This Row],[WCAG 2.1 Success Criteria]] &_xlfn.CONCAT(" (Level ") &Final_Report[[#This Row],[WCAG 2.1 Conformance Level]] &_xlfn.CONCAT("), ") &IF(Final_Report[[#This Row],[Chrome/JAWS]]="Applicable","Windows_11, Chrome, JAWS, ", " ") &IF(Final_Report[[#This Row],[FF/NVDA]]="Applicable", "Windows_11, Firefox, NVDA, ", " ") &IF(Final_Report[[#This Row],[Chrome/NVDA]]="Applicable", "Windows_11, Chrome, NVDA, ", " ") &IF(Final_Report[[#This Row],[iOS/VO]]="Applicable", "iOS Tablet, VoiceOver, ", " ") &IF(Final_Report[[#This Row],[Mac/Safari/VO]]="Applicable", "macOS_12, Safari, VoiceOver, ", " ") &IF(Final_Report[[#This Row],[Mac/Chrome/VO]]="Applicable", "macOS_12, Chrome, VoiceOver, ", " ") &IF(Final_Report[[#This Row],[Android/Talkback]]="Applicable", "TalkBack, Android Tablet", " ") ) &", " &IF(ISERROR(FIND("iOS 13",INDEX(Keyword[Component Keyword],MATCH(TRUE,INDEX((Keyword[Component Keyword]<>0),0),0)))=FALSE),INDEX(Keyword[Component Keyword],MATCH(TRUE,INDEX((Keyword[Component Keyword]<>0),0),0)),SUBSTITUTE(INDEX(Keyword[Component Keyword],MATCH(TRUE,INDEX((Keyword[Component Keyword]<>0),0),0)),"iOS 13","iOS")),",",""))+1))-1)*999+1,999))))} -> N/A (Level N/A), Windows_11, Chrome, JAWS, NVDA, Accessibility, Audit, Marketing, MLM-XL, MLVISION, MyLab, US, VPAT | AM4: {=CONCATENATE(LEFT(AH4, SEARCH(" ", AH4) -1),", ",Labels[Labels])} -> #VALUE! | AN4: =IF(AJ4="Blocker","1 - Critical - showstopper",IF(AJ4="Critical","1 - Critical - showstopper",IF(AJ4="Major","1 - Critical - showstopper",IF(AJ4="Minor","3 - Medium - minor functionality broken",IF(AJ4="Trivial","4 - Low - cosmetic or usability"))))) -> FALSE | BC4: =VLOOKUP('Final Report'!D4,'Issue Variable'!A:N,11,FALSE) -> #N/A
A5: P2 | B5: =VLOOKUP(A5,URL[],2,0) -> Course Home - Calendar | C5: =VLOOKUP(A5,URL[],3,0) -> 0 | D5: Colour | E5: Color alone used to convey information | F5: Colour (#C0C0C0) alone is used to indicate the "Gray text" information on the table - Known issue - ACDS-248696 known check done valid- dilip | G5: Applicable | I5: Applicable | P5: naveen.lagishetty | Q5: No QA Needed | S5: No | T5: =IF(Final_Report[[#This Row],[Move to Report]]="Yes",VLOOKUP(E5,IssueVariable[],3,0),"N/A") -> N/A | U5: =IF(Final_Report[[#This Row],[Move to Report]]="Yes",VLOOKUP(E5,IssueVariable[],4,0),"N/A") -> N/A | V5: =Final_Report[[#This Row],[Issue Description]] -> N/A | X5: =Final_Report[[#This Row],[Code Snippet]] -> 0 | Y5: =IF(Final_Report[[#This Row],[Move to Report]]="Yes",VLOOKUP(E5,IssueVariable[],5,0),"N/A") -> N/A | Z5: =Final_Report[[#This Row],[Expected Result]] -> N/A | AA5: =IF(Final_Report[[#This Row],[Move to Report]]="Yes",VLOOKUP(E5,IssueVariable[],6,0),"N/A") -> N/A | AB5: =IF(Final_Report[[#This Row],[Move to Report]]="Yes",VLOOKUP(E5,IssueVariable[],7,0),"N/A") -> N/A | AC5: =Final_Report[[#This Row],[Recommendation]] -> N/A | AE5: =IF(Final_Report[[#This Row],[Move to Report]]="Yes",VLOOKUP(E5,IssueVariable[],8,0),"N/A") -> N/A | AF5: =Final_Report[[#This Row],[Steps to Reproduce]] -> N/A | AG5: =IF(Final_Report[[#This Row],[Move to Report]]="Yes",VLOOKUP(E5,IssueVariable[],9,0),"N/A") -> N/A | AH5: =IF(Final_Report[[#This Row],[Move to Report]]="Yes",VLOOKUP(E5,IssueVariable[],10,0),"N/A") -> N/A | AK5: {=Table95[Tested on]} -> Windows: 11 MAC OS: 12 iOS: 15 Android OS: 10 | AL5: {=_xlfn.TEXTJOIN(", ",TRUE,_xlfn.UNIQUE(TRIM(MID(SUBSTITUTE((Final_Report[[#This Row],[WCAG 2.1 Success Criteria]] &_xlfn.CONCAT(" (Level ") &Final_Report[[#This Row],[WCAG 2.1 Conformance Level]] &_xlfn.CONCAT("), ") &IF(Final_Report[[#This Row],[Chrome/JAWS]]="Applicable","Windows_11, Chrome, JAWS, ", " ") &IF(Final_Report[[#This Row],[FF/NVDA]]="Applicable", "Windows_11, Firefox, NVDA, ", " ") &IF(Final_Report[[#This Row],[Chrome/NVDA]]="Applicable", "Windows_11, Chrome, NVDA, ", " ") &IF(Final_Report[[#This Row],[iOS/VO]]="Applicable", "iOS Tablet, VoiceOver, ", " ") &IF(Final_Report[[#This Row],[Mac/Safari/VO]]="Applicable", "macOS_12, Safari, VoiceOver, ", " ") &IF(Final_Report[[#This Row],[Mac/Chrome/VO]]="Applicable", "macOS_12, Chrome, VoiceOver, ", " ") &IF(Final_Report[[#This Row],[Android/Talkback]]="Applicable", "TalkBack, Android Tablet", " ") ) &", " &IF(ISERROR(FIND("iOS 13",INDEX(Keyword[Component Keyword],MATCH(TRUE,INDEX((Keyword[Component Keyword]<>0),0),0)))=FALSE),INDEX(Keyword[Component Keyword],MATCH(TRUE,INDEX((Keyword[Component Keyword]<>0),0),0)),SUBSTITUTE(INDEX(Keyword[Component Keyword],MATCH(TRUE,INDEX((Keyword[Component Keyword]<>0),0),0)),"iOS 13","iOS")),",",REPT(" ",999)),(ROW($AAN$1:INDEX($AAX:$AAX,LEN((Final_Report[[#This Row],[WCAG 2.1 Success Criteria]] &_xlfn.CONCAT(" (Level ") &Final_Report[[#This Row],[WCAG 2.1 Conformance Level]] &_xlfn.CONCAT("), ") &IF(Final_Report[[#This Row],[Chrome/JAWS]]="Applicable","Windows_11, Chrome, JAWS, ", " ") &IF(Final_Report[[#This Row],[FF/NVDA]]="Applicable", "Windows_11, Firefox, NVDA, ", " ") &IF(Final_Report[[#This Row],[Chrome/NVDA]]="Applicable", "Windows_11, Chrome, NVDA, ", " ") &IF(Final_Report[[#This Row],[iOS/VO]]="Applicable", "iOS Tablet, VoiceOver, ", " ") &IF(Final_Report[[#This Row],[Mac/Safari/VO]]="Applicable", "macOS_12, Safari, VoiceOver, ", " ") &IF(Final_Report[[#This Row],[Mac/Chrome/VO]]="Applicable", "macOS_12, Chrome, VoiceOver, ", " ") &IF(Final_Report[[#This Row],[Android/Talkback]]="Applicable", "TalkBack, Android Tablet", " ") ) &", " &IF(ISERROR(FIND("iOS 13",INDEX(Keyword[Component Keyword],MATCH(TRUE,INDEX((Keyword[Component Keyword]<>0),0),0)))=FALSE),INDEX(Keyword[Component Keyword],MATCH(TRUE,INDEX((Keyword[Component Keyword]<>0),0),0)),SUBSTITUTE(INDEX(Keyword[Component Keyword],MATCH(TRUE,INDEX((Keyword[Component Keyword]<>0),0),0)),"iOS 13","iOS")))-LEN(SUBSTITUTE((Final_Report[[#This Row],[WCAG 2.1 Success Criteria]] &_xlfn.CONCAT(" (Level ") &Final_Report[[#This Row],[WCAG 2.1 Conformance Level]] &_xlfn.CONCAT("), ") &IF(Final_Report[[#This Row],[Chrome/JAWS]]="Applicable","Windows_11, Chrome, JAWS, ", " ") &IF(Final_Report[[#This Row],[FF/NVDA]]="Applicable", "Windows_11, Firefox, NVDA, ", " ") &IF(Final_Report[[#This Row],[Chrome/NVDA]]="Applicable", "Windows_11, Chrome, NVDA, ", " ") &IF(Final_Report[[#This Row],[iOS/VO]]="Applicable", "iOS Tablet, VoiceOver, ", " ") &IF(Final_Report[[#This Row],[Mac/Safari/VO]]="Applicable", "macOS_12, Safari, VoiceOver, ", " ") &IF(Final_Report[[#This Row],[Mac/Chrome/VO]]="Applicable", "macOS_12, Chrome, VoiceOver, ", " ") &IF(Final_Report[[#This Row],[Android/Talkback]]="Applicable", "TalkBack, Android Tablet", " ") ) &", " &IF(ISERROR(FIND("iOS 13",INDEX(Keyword[Component Keyword],MATCH(TRUE,INDEX((Keyword[Component Keyword]<>0),0),0)))=FALSE),INDEX(Keyword[Component Keyword],MATCH(TRUE,INDEX((Keyword[Component Keyword]<>0),0),0)),SUBSTITUTE(INDEX(Keyword[Component Keyword],MATCH(TRUE,INDEX((Keyword[Component Keyword]<>0),0),0)),"iOS 13","iOS")),",",""))+1))-1)*999+1,999))))} -> N/A (Level N/A), Windows_11, Chrome, JAWS, NVDA, Accessibility, Audit, Marketing, MLM-XL, MLVISION, MyLab, US, VPAT | AM5: {=CONCATENATE(LEFT(AH5, SEARCH(" ", AH5) -1),", ",Labels[Labels])} -> #VALUE! | AN5: =IF(AJ5="Blocker","1 - Critical - showstopper",IF(AJ5="Critical","1 - Critical - showstopper",IF(AJ5="Major","1 - Critical - showstopper",IF(AJ5="Minor","3 - Medium - minor functionality broken",IF(AJ5="Trivial","4 - Low - cosmetic or usability"))))) -> FALSE | AR5: Known issue - ACDS-248696 | BC5: =VLOOKUP('Final Report'!D5,'Issue Variable'!A:N,11,FALSE) -> #N/A
A6: P2 | B6: =VLOOKUP(A6,URL[],2,0) -> Course Home - Calendar | C6: =VLOOKUP(A6,URL[],3,0) -> 0 | D6: Content | E6: Element type defined inappropriately | F6: The <article> element was incorrectly defined on the tested page which resulted in a confusing experience for screen reader users - Known issue - ACDS-248691 known check done valid- dilip | G6: Applicable | H6: Applicable | I6: Applicable | P6: naveen.lagishetty | Q6: No QA Needed | S6: No | T6: =IF(Final_Report[[#This Row],[Move to Report]]="Yes",VLOOKUP(E6,IssueVariable[],3,0),"N/A") -> N/A | U6: =IF(Final_Report[[#This Row],[Move to Report]]="Yes",VLOOKUP(E6,IssueVariable[],4,0),"N/A") -> N/A | V6: =Final_Report[[#This Row],[Issue Description]] -> N/A | X6: =Final_Report[[#This Row],[Code Snippet]] -> 0 | Y6: =IF(Final_Report[[#This Row],[Move to Report]]="Yes",VLOOKUP(E6,IssueVariable[],5,0),"N/A") -> N/A | Z6: =Final_Report[[#This Row],[Expected Result]] -> N/A | AA6: =IF(Final_Report[[#This Row],[Move to Report]]="Yes",VLOOKUP(E6,IssueVariable[],6,0),"N/A") -> N/A | AB6: =IF(Final_Report[[#This Row],[Move to Report]]="Yes",VLOOKUP(E6,IssueVariable[],7,0),"N/A") -> N/A | AC6: =Final_Report[[#This Row],[Recommendation]] -> N/A | AE6: =IF(Final_Report[[#This Row],[Move to Report]]="Yes",VLOOKUP(E6,IssueVariable[],8,0),"N/A") -> N/A | AF6: =Final_Report[[#This Row],[Steps to Reproduce]] -> N/A | AG6: =IF(Final_Report[[#This Row],[Move to Report]]="Yes",VLOOKUP(E6,IssueVariable[],9,0),"N/A") -> N/A | AH6: =IF(Final_Report[[#This Row],[Move to Report]]="Yes",VLOOKUP(E6,IssueVariable[],10,0),"N/A") -> N/A | AK6: {=Table95[Tested on]} -> Windows: 11 MAC OS: 12 iOS: 15 Android OS: 10 | AL6: {=_xlfn.TEXTJOIN(", ",TRUE,_xlfn.UNIQUE(TRIM(MID(SUBSTITUTE((Final_Report[[#This Row],[WCAG 2.1 Success Criteria]] &_xlfn.CONCAT(" (Level ") &Final_Report[[#This Row],[WCAG 2.1 Conformance Level]] &_xlfn.CONCAT("), ") &IF(Final_Report[[#This Row],[Chrome/JAWS]]="Applicable","Windows_11, Chrome, JAWS, ", " ") &IF(Final_Report[[#This Row],[FF/NVDA]]="Applicable", "Windows_11, Firefox, NVDA, ", " ") &IF(Final_Report[[#This Row],[Chrome/NVDA]]="Applicable", "Windows_11, Chrome, NVDA, ", " ") &IF(Final_Report[[#This Row],[iOS/VO]]="Applicable", "iOS Tablet, VoiceOver, ", " ") &IF(Final_Report[[#This Row],[Mac/Safari/VO]]="Applicable", "macOS_12, Safari, VoiceOver, ", " ") &IF(Final_Report[[#This Row],[Mac/Chrome/VO]]="Applicable", "macOS_12, Chrome, VoiceOver, ", " ") &IF(Final_Report[[#This Row],[Android/Talkback]]="Applicable", "TalkBack, Android Tablet", " ") ) &", " &IF(ISERROR(FIND("iOS 13",INDEX(Keyword[Component Keyword],MATCH(TRUE,INDEX((Keyword[Component Keyword]<>0),0),0)))=FALSE),INDEX(Keyword[Component Keyword],MATCH(TRUE,INDEX((Keyword[Component Keyword]<>0),0),0)),SUBSTITUTE(INDEX(Keyword[Component Keyword],MATCH(TRUE,INDEX((Keyword[Component Keyword]<>0),0),0)),"iOS 13","iOS")),",",REPT(" ",999)),(ROW($AAN$1:INDEX($AAX:$AAX,LEN((Final_Report[[#This Row],[WCAG 2.1 Success Criteria]] &_xlfn.CONCAT(" (Level ") &Final_Report[[#This Row],[WCAG 2.1 Conformance Level]] &_xlfn.CONCAT("), ") &IF(Final_Report[[#This Row],[Chrome/JAWS]]="Applicable","Windows_11, Chrome, JAWS, ", " ") &IF(Final_Report[[#This Row],[FF/NVDA]]="Applicable", "Windows_11, Firefox, NVDA, ", " ") &IF(Final_Report[[#This Row],[Chrome/NVDA]]="Applicable", "Windows_11, Chrome, NVDA, ", " ") &IF(Final_Report[[#This Row],[iOS/VO]]="Applicable", "iOS Tablet, VoiceOver, ", " ") &IF(Final_Report[[#This Row],[Mac/Safari/VO]]="Applicable", "macOS_12, Safari, VoiceOver, ", " ") &IF(Final_Report[[#This Row],[Mac/Chrome/VO]]="Applicable", "macOS_12, Chrome, VoiceOver, ", " ") &IF(Final_Report[[#This Row],[Android/Talkback]]="Applicable", "TalkBack, Android Tablet", " ") ) &", " &IF(ISERROR(FIND("iOS 13",INDEX(Keyword[Component Keyword],MATCH(TRUE,INDEX((Keyword[Component Keyword]<>0),0),0)))=FALSE),INDEX(Keyword[Component Keyword],MATCH(TRUE,INDEX((Keyword[Component Keyword]<>0),0),0)),SUBSTITUTE(INDEX(Keyword[Component Keyword],MATCH(TRUE,INDEX((Keyword[Component Keyword]<>0),0),0)),"iOS 13","iOS")))-LEN(SUBSTITUTE((Final_Report[[#This Row],[WCAG 2.1 Success Criteria]] &_xlfn.CONCAT(" (Level ") &Final_Report[[#This Row],[WCAG 2.1 Conformance Level]] &_xlfn.CONCAT("), ") &IF(Final_Report[[#This Row],[Chrome/JAWS]]="Applicable","Windows_11, Chrome, JAWS, ", " ") &IF(Final_Report[[#This Row],[FF/NVDA]]="Applicable", "Windows_11, Firefox, NVDA, ", " ") &IF(Final_Report[[#This Row],[Chrome/NVDA]]="Applicable", "Windows_11, Chrome, NVDA, ", " ") &IF(Final_Report[[#This Row],[iOS/VO]]="Applicable", "iOS Tablet, VoiceOver, ", " ") &IF(Final_Report[[#This Row],[Mac/Safari/VO]]="Applicable", "macOS_12, Safari, VoiceOver, ", " ") &IF(Final_Report[[#This Row],[Mac/Chrome/VO]]="Applicable", "macOS_12, Chrome, VoiceOver, ", " ") &IF(Final_Report[[#This Row],[Android/Talkback]]="Applicable", "TalkBack, Android Tablet", " ") ) &", " &IF(ISERROR(FIND("iOS 13",INDEX(Keyword[Component Keyword],MATCH(TRUE,INDEX((Keyword[Component Keyword]<>0),0),0)))=FALSE),INDEX(Keyword[Component Keyword],MATCH(TRUE,INDEX((Keyword[Component Keyword]<>0),0),0)),SUBSTITUTE(INDEX(Keyword[Component Keyword],MATCH(TRUE,INDEX((Keyword[Component Keyword]<>0),0),0)),"iOS 13","iOS")),",",""))+1))-1)*999+1,999))))} -> N/A (Level N/A), Windows_11, Chrome, JAWS, Firefox, NVDA, Accessibility, Audit, Marketing, MLM-XL, MLVISION, MyLab, US, VPAT | AM6: {=CONCATENATE(LEFT(AH6, SEARCH(" ", AH6) -1),", ",Labels[Labels])} -> #VALUE! | AN6: =IF(AJ6="Blocker","1 - Critical - showstopper",IF(AJ6="Critical","1 - Critical - showstopper",IF(AJ6="Major","1 - Critical - showstopper",IF(AJ6="Minor","3 - Medium - minor functionality broken",IF(AJ6="Trivial","4 - Low - cosmetic or usability"))))) -> FALSE | AR6: Known issue - ACDS-248691 | BC6: =VLOOKUP('Final Report'!D6,'Issue Variable'!A:N,11,FALSE) -> #N/A
A7: P2 | B7: =VLOOKUP(A7,URL[],2,0) -> Course Home - Calendar | C7: =VLOOKUP(A7,URL[],3,0) -> 0 | D7: Focus | E7: Focus not clearly visible | F7: When user activate "0%, Overall Score" button it shows "Show progress and scores" toggle button where focus outline is not clearly visible. | G7: Applicable | I7: Applicable | M7: Applicable | P7: naveen.lagishetty | Q7: No QA Needed | S7: Yes | T7: Web: Course Home - Calendar: Focus not clearly visible | U7: When accessing the page through the keyboard, it is not possible to visually identify user’s current location on the menu items such as "Show progress and scores" toggle button (that becomes available on activating "0%, Overall Score" button). Focus indicator is not clearly visible as the user tabs through using a keyboard. | V7: =Final_Report[[#This Row],[Issue Description]] -> When accessing the page through the keyboard, it is not possible to visually identify user’s current location on the menu items such as "Show progress and scores" toggle button (that becomes available on activating "0%, Overall Score" button). Focus indicator is not clearly visible as the user tabs through using a keyboard. | X7: =Final_Report[[#This Row],[Code Snippet]] -> 0 | Y7: =IF(Final_Report[[#This Row],[Move to Report]]="Yes",VLOOKUP(E7,IssueVariable[],5,0),"N/A") -> When the keyboard-only users navigate through the above-discussed content, there should be a clear visual indication to user when their focus moves from one interactive element to another. | Z7: =Final_Report[[#This Row],[Expected Result]] -> When the keyboard-only users navigate through the above-discussed content, there should be a clear visual indication to user when their focus moves from one interactive element to another. | AA7: =IF(Final_Report[[#This Row],[Move to Report]]="Yes",VLOOKUP(E7,IssueVariable[],6,0),"N/A") -> On screen, visual focus indication helps users find out about their location on the page. This is found very helpful by users with low vision, elderly users, keyboard-only users and users with mobility impairments. In the absence of clear focus indication, users would find it difficult to access the page information. | AB7: =IF(Final_Report[[#This Row],[Move to Report]]="Yes",VLOOKUP(E7,IssueVariable[],7,0),"N/A") -> Provide clear visual indication to user when their focus moves from one interactive element to another. This will help all users while accessing the page content especially users with visual, mobility and learning impairments. | AC7: =Final_Report[[#This Row],[Recommendation]] -> Provide clear visual indication to user when their focus moves from one interactive element to another. This will help all users while accessing the page content especially users with visual, mobility and learning impairments. | AD7: URL: https://www.pearsonmylabandmastering.com/northamerica Username: Aqavpat-edu1 Password: AuditPa559338 Course Title: AQA_VPAT_Kotler_Principles of Marketing 19e Course Id: auditor49388 1. Launch the above URL with the given credentials and navigate to the mentioned course | AE7: 2. Navigate to Course Home > Calendar interactive element and activate it. 3. Navigate to "0%, Overall Score" button and activate. 4. Navigate with tab key and oberve focus on "Show progress and scores" toggle button. | AF7: =Final_Report[[#This Row],[Steps to Reproduce]] -> 2. Navigate to Course Home > Calendar interactive element and activate it. 3. Navigate to "0%, Overall Score" button and activate. 4. Navigate with tab key and oberve focus on "Show progress and scores" toggle button. | AG7: =IF(Final_Report[[#This Row],[Move to Report]]="Yes",VLOOKUP(E7,IssueVariable[],9,0),"N/A") -> AA | AH7: =IF(Final_Report[[#This Row],[Move to Report]]="Yes",VLOOKUP(E7,IssueVariable[],10,0),"N/A") -> 2.4.7 Focus Visible | AI7: Marketing_7 | AJ7: Minor | AK7: {=Table95[Tested on]} -> Windows: 11 MAC OS: 12 iOS: 15 Android OS: 10 | AL7: {=_xlfn.TEXTJOIN(", ",TRUE,_xlfn.UNIQUE(TRIM(MID(SUBSTITUTE((Final_Report[[#This Row],[WCAG 2.1 Success Criteria]] &_xlfn.CONCAT(" (Level ") &Final_Report[[#This Row],[WCAG 2.1 Conformance Level]] &_xlfn.CONCAT("), ") &IF(Final_Report[[#This Row],[Chrome/JAWS]]="Applicable","Windows_11, Chrome, JAWS, ", " ") &IF(Final_Report[[#This Row],[FF/NVDA]]="Applicable", "Windows_11, Firefox, NVDA, ", " ") &IF(Final_Report[[#This Row],[Chrome/NVDA]]="Applicable", "Windows_11, Chrome, NVDA, ", " ") &IF(Final_Report[[#This Row],[iOS/VO]]="Applicable", "iOS Tablet, VoiceOver, ", " ") &IF(Final_Report[[#This Row],[Mac/Safari/VO]]="Applicable", "macOS_12, Safari, VoiceOver, ", " ") &IF(Final_Report[[#This Row],[Mac/Chrome/VO]]="Applicable", "macOS_12, Chrome, VoiceOver, ", " ") &IF(Final_Report[[#This Row],[Android/Talkback]]="Applicable", "TalkBack, Android Tablet", " ") ) &", " &IF(ISERROR(FIND("iOS 13",INDEX(Keyword[Component Keyword],MATCH(TRUE,INDEX((Keyword[Component Keyword]<>0),0),0)))=FALSE),INDEX(Keyword[Component Keyword],MATCH(TRUE,INDEX((Keyword[Component Keyword]<>0),0),0)),SUBSTITUTE(INDEX(Keyword[Component Keyword],MATCH(TRUE,INDEX((Keyword[Component Keyword]<>0),0),0)),"iOS 13","iOS")),",",REPT(" ",999)),(ROW($AAN$1:INDEX($AAX:$AAX,LEN((Final_Report[[#This Row],[WCAG 2.1 Success Criteria]] &_xlfn.CONCAT(" (Level ") &Final_Report[[#This Row],[WCAG 2.1 Conformance Level]] &_xlfn.CONCAT("), ") &IF(Final_Report[[#This Row],[Chrome/JAWS]]="Applicable","Windows_11, Chrome, JAWS, ", " ") &IF(Final_Report[[#This Row],[FF/NVDA]]="Applicable", "Windows_11, Firefox, NVDA, ", " ") &IF(Final_Report[[#This Row],[Chrome/NVDA]]="Applicable", "Windows_11, Chrome, NVDA, ", " ") &IF(Final_Report[[#This Row],[iOS/VO]]="Applicable", "iOS Tablet, VoiceOver, ", " ") &IF(Final_Report[[#This Row],[Mac/Safari/VO]]="Applicable", "macOS_12, Safari, VoiceOver, ", " ") &IF(Final_Report[[#This Row],[Mac/Chrome/VO]]="Applicable", "macOS_12, Chrome, VoiceOver, ", " ") &IF(Final_Report[[#This Row],[Android/Talkback]]="Applicable", "TalkBack, Android Tablet", " ") ) &", " &IF(ISERROR(FIND("iOS 13",INDEX(Keyword[Component Keyword],MATCH(TRUE,INDEX((Keyword[Component Keyword]<>0),0),0)))=FALSE),INDEX(Keyword[Component Keyword],MATCH(TRUE,INDEX((Keyword[Component Keyword]<>0),0),0)),SUBSTITUTE(INDEX(Keyword[Component Keyword],MATCH(TRUE,INDEX((Keyword[Component Keyword]<>0),0),0)),"iOS 13","iOS")))-LEN(SUBSTITUTE((Final_Report[[#This Row],[WCAG 2.1 Success Criteria]] &_xlfn.CONCAT(" (Level ") &Final_Report[[#This Row],[WCAG 2.1 Conformance Level]] &_xlfn.CONCAT("), ") &IF(Final_Report[[#This Row],[Chrome/JAWS]]="Applicable","Windows_11, Chrome, JAWS, ", " ") &IF(Final_Report[[#This Row],[FF/NVDA]]="Applicable", "Windows_11, Firefox, NVDA, ", " ") &IF(Final_Report[[#This Row],[Chrome/NVDA]]="Applicable", "Windows_11, Chrome, NVDA, ", " ") &IF(Final_Report[[#This Row],[iOS/VO]]="Applicable", "iOS Tablet, VoiceOver, ", " ") &IF(Final_Report[[#This Row],[Mac/Safari/VO]]="Applicable", "macOS_12, Safari, VoiceOver, ", " ") &IF(Final_Report[[#This Row],[Mac/Chrome/VO]]="Applicable", "macOS_12, Chrome, VoiceOver, ", " ") &IF(Final_Report[[#This Row],[Android/Talkback]]="Applicable", "TalkBack, Android Tablet", " ") ) &", " &IF(ISERROR(FIND("iOS 13",INDEX(Keyword[Component Keyword],MATCH(TRUE,INDEX((Keyword[Component Keyword]<>0),0),0)))=FALSE),INDEX(Keyword[Component Keyword],MATCH(TRUE,INDEX((Keyword[Component Keyword]<>0),0),0)),SUBSTITUTE(INDEX(Keyword[Component Keyword],MATCH(TRUE,INDEX((Keyword[Component Keyword]<>0),0),0)),"iOS 13","iOS")),",",""))+1))-1)*999+1,999))))} -> 2.4.7 Focus Visible (Level AA), Windows_11, Chrome, JAWS, NVDA, TalkBack, Android Tablet, Accessibility, Audit, Marketing, MLM-XL, MLVISION, MyLab, US, VPAT | AM7: {=CONCATENATE(LEFT(AH7, SEARCH(" ", AH7) -1),", ",Labels[Labels])} -> 2.4.7, Accessibility, Audit, Marketing, MLM-XL, MLVISION, MyLab, US, VPAT | AN7: =IF(AJ7="Blocker","1 - Critical - showstopper",IF(AJ7="Critical","1 - Critical - showstopper",IF(AJ7="Major","1 - Critical - showstopper",IF(AJ7="Minor","3 - Medium - minor functionality broken",IF(AJ7="Trivial","4 - Low - cosmetic or usability"))))) -> 3 - Medium - minor functionality broken | AO7: naveen.lagishetty | AP7: 5 | AS7: 5 | AT7: manasi.varma | AU7: issue is correct but we have flagged color issue it will solve focus problem also | AV7: Technical Issues | AW7: 5 | AX7: Delete - QA | BC7: =VLOOKUP('Final Report'!D7,'Issue Variable'!A:N,11,FALSE) -> #N/A
